Ошибки – неотъемлемая часть разработки.
Из них нам обычно приходится работать с несколькими типами ошибок.

Один из наиболее часто встречающихся,
это так называемый `ReferenceError`. 
`Reference` – значит некая ссылка, соответственно, `Error` – ошибка.

`Uncaught` – непойманная ошибка, что значит поймать ошибку, мы сейчас тоже разберемся постепенно.
```js
console.log(x);
```
Соответственно, каждый раз, когда мы видим `ReferenceError`, это значит, что в нашей программе
мы пытаемся использовать имя переменной либо ключа объекта, которого у нас не существует.

В простейших ситуациях мы можем встретить синтаксические ошибки. Это значит, что мы где-то забыли скобку, где-то мы забыли кавычку или еще что-то.

Но чаще всего мы встречаемся либо с `ReferenceError`, либо с `TypeError`, что такое `TypeError`.
```js 
const x = 1;
x();
```
Представим, что у нас всё-таки есть этот самый Х. Х, который равен, условно, 1. Дальше мы пытаемся вызвать этот Х, как будто бы мы работаем с функцией. Мы получаем непойманную ошибку, типа `TypeError`. Соответственно, ошибка типа, будет говорить, что Х вообще-то не функция.

При этом мы с вами можем и самостоятельно создавать ошибки. 
```js
function sum(a,b) {
  if (typeof a !== 'number' || typeof b !== number) {
    throw new Error("В функцию не переданы числа для сложения");
  }
  return a + b;
};
```
Мы используем ключевое слово `throw`, то бишь пробрось. Дальше говорим – новую ошибку (Error).

Мы сделали защиту от дурака, если пришел дурак, соответственно, он не может пользоваться нашей функцией.
Не всегда, не всегда это требуется.

Для того, чтобы наше приложение всё-таки не падало в момент ошибок, например, вот такое, мы видим, что может случиться ошибка, мы можем
использовать конструкцию `try` `catch`.
```js
try {
 sum()
} catch(err) {
 console.error(err.message);
}
```
Что эта конструкция делает? В секции `try` мы пытаемся выполнить какой-то код, допустим, мы пытаемся вызвать сумму и ничего не передать. Соответственно, `catch` будет
отлавливать нашу ошибку, и эту ошибку, допустим,
я могу вывести в `console` либо `log`, либо могу вывести в `console.error()`. 

Еще раз давайте посмотрим, у нас есть функция, я эту функцию пытаюсь вызвать. Я понимаю, что вызов приведет к ошибке. Но я ожидаю, что мое приложение не сломается.


























